Workbook
Name bev: [1]Sheet2!$H$7:$H$12
Name bg: [1]Sheet2!$H$2:$H$6
Name candy: [1]Sheet2!$H$13:$H$17
Name cmeat: [1]Sheet2!$H$22:$H$23
Name Co_List: [1]Sheet2!$A$2:$A$27
Name condiment: [1]Sheet2!$H$24:$H$27
Name dairyp: [1]Sheet2!$H$28:$H$32
Name e: [1]Sheet3!$D$6:$D$10
Name fandv: [1]Sheet2!$H$18:$H$21
Name grains: [1]Sheet2!$H$37:$H$40
Name jams: [1]Sheet2!$H$41:$H$43
Name n: [1]Sheet3!$E$6:$E$10
Name ne: [1]Sheet3!$G$6:$G$10
Name nuts: [1]Sheet2!$H$33:$H$36
Name nw: [1]Sheet3!$F$6:$F$10
Name oil: [1]Sheet2!$H$44:$H$45
Name pasta: [1]Sheet2!$H$46:$H$50
Name prod_cat: [1]Sheet2!$L$2:$L$16
Name pt: [1]Sheet2!$E$2:$E$4
Name s: [1]Sheet3!$H$6:$H$10
Name se: [1]Sheet3!$J$6:$J$10
Name soup: [1]Sheet2!$H$55:$H$58
Name sw: [1]Sheet3!$I$6:$I$10
Name team: [1]Sheet2!$C$2:$C$9
Name w: [1]Sheet3!$C$6:$C$10

Sheet Cover Page
B2: 2021 Sales Report
B6: Contents
C7: All Sales
C8: Team Results | D8: North
D9: South
D10: East
D11: West
C12: Chart
C13: Sales Analysis
C14: New Staff

Sheet All Sales
A1: Month | B1: Employee | C1: Employee | D1: First Name | E1: Last Name | F1: Sales Area | G1: Sales Amount | H1: Payment Type | I1: Targets | J1: Commissions | L1: Commission
A2: 44197 | B2: Reza Jafari | C2: =TRIM(B2) -> Reza Jafari | D2: Reza | E2: Jafari | F2: East | G2: 2954.7 | H2: Cash | I2: 15000 | J2: =IF(G2>=I2,G2*$L$2,0) -> 0 | L2: 0.1 | R2: Back to Cover Page
A3: 44197 | B3: Bryan Maldonado | C3: =TRIM(B3) -> Bryan Maldonado | D3: Bryan | E3: Maldonado | F3: East | G3: 6796.8 | H3: Credit Card | I3: 15000 | J3: =IF(G3>=I3,G3*$L$2,0) -> 0
A4: 44197 | B4: Bryan Maldonado | C4: =TRIM(B4) -> Bryan Maldonado | D4: Bryan | E4: Maldonado | F4: East | G4: 8188 | H4: On Account | I4: 15000 | J4: =IF(G4>=I4,G4*$L$2,0) -> 0
A5: 44197 | B5: Reza Jafari | C5: =TRIM(B5) -> Reza Jafari | D5: Reza | E5: Jafari | F5: East | G5: 9058.4 | H5: Credit Card | I5: 15000 | J5: =IF(G5>=I5,G5*$L$2,0) -> 0
A6: 44197 | B6: Bryan Maldonado | C6: =TRIM(B6) -> Bryan Maldonado | D6: Bryan | E6: Maldonado | F6: East | G6: 12096 | H6: On Account | I6: 15000 | J6: =IF(G6>=I6,G6*$L$2,0) -> 0
A7: 44197 | B7: Ashley Almanza | C7: =TRIM(B7) -> Ashley Almanza | D7: Ashley | E7: Almanza | F7: East | G7: 15029 | H7: Cash | I7: 15000 | J7: =IF(G7>=I7,G7*$L$2,0) -> 1502.9
A8: 44197 | B8: Ashley Almanza | C8: =TRIM(B8) -> Ashley Almanza | D8: Ashley | E8: Almanza | F8: East | G8: 15264 | H8: Cash | I8: 15000 | J8: =IF(G8>=I8,G8*$L$2,0) -> 1526.4
A9: 44197 | B9: Ashley Almanza | C9: =TRIM(B9) -> Ashley Almanza | D9: Ashley | E9: Almanza | F9: East | G9: 17353.6 | H9: Credit Card | I9: 15000 | J9: =IF(G9>=I9,G9*$L$2,0) -> 1735.36
A10: 44197 | B10: Derek Godwin | C10: =TRIM(B10) -> Derek Godwin | D10: Derek | E10: Godwin | F10: East | G10: 20140 | H10: On Account | I10: 15000 | J10: =IF(G10>=I10,G10*$L$2,0) -> 2014
A11: 44197 | B11: Derek Godwin | C11: =TRIM(B11) -> Derek Godwin | D11: Derek | E11: Godwin | F11: East | G11: 35649 | H11: Credit Card | I11: 15000 | J11: =IF(G11>=I11,G11*$L$2,0) -> 3564.9
A12: 44228 | B12: Gordon Beswick | C12: =TRIM(B12) -> Gordon Beswick | D12: Gordon | E12: Beswick | F12: East | G12: 7717.5 | H12: On Account | I12: 15000 | J12: =IF(G12>=I12,G12*$L$2,0) -> 0
A13: 44228 | B13: Gordon Beswick | C13: =TRIM(B13) -> Gordon Beswick | D13: Gordon | E13: Beswick | F13: East | G13: 11617.6 | H13: Cash | I13: 15000 | J13: =IF(G13>=I13,G13*$L$2,0) -> 0
A14: 44228 | B14: Derek Godwin | C14: =TRIM(B14) -> Derek Godwin | D14: Derek | E14: Godwin | F14: East | G14: 19431 | H14: Cash | I14: 15000 | J14: =IF(G14>=I14,G14*$L$2,0) -> 1943.1
... A292: 44531 | B292: Olivia Cheung | C292: =TRIM(B292) -> Olivia Cheung | D292: Olivia | E292: Cheung | F292: South | G292: 43593.6 | H292: Cash | I292: 15000 | J292: =IF(G292>=I292,G292*$L$2,0) -> 4359.36
A293: 44197 | C293: =TRIM(B293) | F293: West | G293: 3637.21 | H293: Credit Card | I293: 15000 | J293: =IF(G293>=I293,G293*$L$2,0) -> 0
A294: 44197 | C294: =TRIM(B294) | F294: West | G294: 3918.6 | H294: Cash | I294: 15000 | J294: =IF(G294>=I294,G294*$L$2,0) -> 0
A295: 44197 | C295: =TRIM(B295) | F295: West | G295: 694.54 | H295: On Account | I295: 15000 | J295: =IF(G295>=I295,G295*$L$2,0) -> 0
A296: 44197 | C296: =TRIM(B296) | F296: West | G296: 3112.72 | H296: On Account | I296: 15000 | J296: =IF(G296>=I296,G296*$L$2,0) -> 0
A297: 44197 | C297: =TRIM(B297) | F297: West | G297: 1001.92 | H297: On Account | I297: 15000 | J297: =IF(G297>=I297,G297*$L$2,0) -> 0
A298: 44197 | C298: =TRIM(B298) | F298: West | G298: 1638.56 | H298: Credit Card | I298: 15000 | J298: =IF(G298>=I298,G298*$L$2,0) -> 0
A299: 44197 | C299: =TRIM(B299) | F299: West | G299: 1910.8 | H299: Cash | I299: 15000 | J299: =IF(G299>=I299,G299*$L$2,0) -> 0
A300: 44197 | C300: =TRIM(B300) | F300: West | G300: 765.82 | H300: On Account | I300: 15000 | J300: =IF(G300>=I300,G300*$L$2,0) -> 0
A301: 44197 | C301: =TRIM(B301) | F301: West | G301: 765.86 | H301: Cash | I301: 15000 | J301: =IF(G301>=I301,G301*$L$2,0) -> 0
A302: 44197 | C302: =TRIM(B302) | F302: West | G302: 4671.6 | H302: Credit Card | I302: 15000 | J302: =IF(G302>=I302,G302*$L$2,0) -> 0
A303: 44197 | C303: =TRIM(B303) | F303: West | G303: 1945.6 | H303: Credit Card | I303: 15000 | J303: =IF(G303>=I303,G303*$L$2,0) -> 0
A304: 44197 | C304: =TRIM(B304) | F304: West | G304: 1017.6 | H304: Cash | I304: 15000 | J304: =IF(G304>=I304,G304*$L$2,0) -> 0
A305: 44197 | C305: =TRIM(B305) | F305: West | G305: 909.86 | H305: On Account | I305: 15000 | J305: =IF(G305>=I305,G305*$L$2,0) -> 0
A306: 44197 | B306: Nina McDonald | C306: =TRIM(B306) -> Nina McDonald | D306: Nina | E306: McDonald | F306: West | G306: 6945.4 | H306: On Account | I306: 15000 | J306: =IF(G306>=I306,G306*$L$2,0) -> 0
A307: 44197 | B307: Nina McDonald | C307: =TRIM(B307) -> Nina McDonald | D307: Nina | E307: McDonald | F307: West | G307: 7658.2 | H307: On Account | I307: 15000 | J307: =IF(G307>=I307,G307*$L$2,0) -> 0
A308: 44197 | B308: Ally Bryant | C308: =TRIM(B308) -> Ally Bryant | D308: Ally | E308: Bryant | F308: West | G308: 7658.6 | H308: Cash | I308: 15000 | J308: =IF(G308>=I308,G308*$L$2,0) -> 0
A309: 44197 | B309: Josh Sutherland | C309: =TRIM(B309) -> Josh Sutherland | D309: Josh | E309: Sutherland | F309: West | G309: 9098.6 | H309: On Account | I309: 15000 | J309: =IF(G309>=I309,G309*$L$2,0) -> 0
A310: 44197 | B310: Nina McDonald | C310: =TRIM(B310) -> Nina McDonald | D310: Nina | E310: McDonald | F310: West | G310: 10019.2 | H310: On Account | I310: 15000 | J310: =IF(G310>=I310,G310*$L$2,0) -> 0
A311: 44197 | B311: Ally Bryant | C311: =TRIM(B311) -> Ally Bryant | D311: Ally | E311: Bryant | F311: West | G311: 10176 | H311: Cash | I311: 15000 | J311: =IF(G311>=I311,G311*$L$2,0) -> 0
A312: 44197 | B312: Josh Sutherland | C312: =TRIM(B312) -> Josh Sutherland | D312: Josh | E312: Sutherland | F312: West | G312: 16385.6 | H312: Credit Card | I312: 15000 | J312: =IF(G312>=I312,G312*$L$2,0) -> 1638.56
A313: 44197 | B313: Ally Bryant | C313: =TRIM(B313) -> Ally Bryant | D313: Ally | E313: Bryant | F313: West | G313: 19108 | H313: Cash | I313: 15000 | J313: =IF(G313>=I313,G313*$L$2,0) -> 1910.8
A314: 44197 | B314: Nina McDonald | C314: =TRIM(B314) -> Nina McDonald | D314: Nina | E314: McDonald | F314: West | G314: 19456 | H314: Credit Card | I314: 15000 | J314: =IF(G314>=I314,G314*$L$2,0) -> 1945.6
A315: 44197 | B315: Spencer Cruz | C315: =TRIM(B315) -> Spencer Cruz | D315: Spencer | E315: Cruz | F315: West | G315: 31127.2 | H315: On Account | I315: 15000 | J315: =IF(G315>=I315,G315*$L$2,0) -> 3112.72
A316: 44197 | B316: Spencer Cruz | C316: =TRIM(B316) -> Spencer Cruz | D316: Spencer | E316: Cruz | F316: West | G316: 36372.1 | H316: Credit Card | I316: 15000 | J316: =IF(G316>=I316,G316*$L$2,0) -> 3637.21
A317: 44197 | B317: Ally Bryant | C317: =TRIM(B317) -> Ally Bryant | D317: Ally | E317: Bryant | F317: West | G317: 39186 | H317: Cash | I317: 15000 | J317: =IF(G317>=I317,G317*$L$2,0) -> 3918.6
...

Sheet North
A1: Month | B1: Employee | C1: First Name | D1: Last Name | E1: Sales Area | F1: Sales Amount | G1: Payment Type | H1: Targets | I1: Commissions
A2: 44197 | B2: Chloe Fusaro | C2: Chloe | D2: Fusaro | E2: North | F2: 13310.4 | G2: Credit Card | H2: 15000 | I2: =IF(F2>=H2,F2*'All Sales'!$L$2,0) -> 0
A3: 44197 | B3: David Wilkinson | C3: David | D3: Wilkinson | E3: North | F3: 20366.1 | G3: On Account | H3: 15000 | I3: =IF(F3>=H3,F3*'All Sales'!$L$2,0) -> 2036.61 | K3: Salesperson Name | L3: {=TRANSPOSE(_xlfn.UNIQUE(_xlfn._xlws.SORT(C2:C97)))} -> Charlotte | M3: Chloe | N3: David | O3: Jonah | P3: Sarah
A4: 44197 | B4: David Wilkinson | C4: David | D4: Wilkinson | E4: North | F4: 20880 | G4: Credit Card | H4: 15000 | I4: =IF(F4>=H4,F4*'All Sales'!$L$2,0) -> 2088 | K4: Total Sales | L4: {=SUMIFS($F$2:$F$97,$C$2:$C$97,_xlfn.ANCHORARRAY(L3))} -> 335128.9 | M4: 517004.6 | N4: 289580.8 | O4: 439469.9 | P4: 364649
A5: 44197 | B5: Chloe Fusaro | C5: Chloe | D5: Fusaro | E5: North | F5: 23076.2 | G5: Credit Card | H5: 15000 | I5: =IF(F5>=H5,F5*'All Sales'!$L$2,0) -> 2307.62
A6: 44197 | B6: Chloe Fusaro | C6: Chloe | D6: Fusaro | E6: North | F6: 25560 | G6: Credit Card | H6: 15000 | I6: =IF(F6>=H6,F6*'All Sales'!$L$2,0) -> 2556 | P6: Back to Cover Page
A7: 44228 | B7: David Wilkinson | C7: David | D7: Wilkinson | E7: North | F7: 13479.4 | G7: On Account | H7: 15000 | I7: =IF(F7>=H7,F7*'All Sales'!$L$2,0) -> 0
A8: 44228 | B8: Chloe Fusaro | C8: Chloe | D8: Fusaro | E8: North | F8: 16604.4 | G8: Cash | H8: 15000 | I8: =IF(F8>=H8,F8*'All Sales'!$L$2,0) -> 1660.44
A9: 44228 | B9: Sarah Gibbs | C9: Sarah | D9: Gibbs | E9: North | F9: 22176 | G9: Cash | H9: 15000 | I9: =IF(F9>=H9,F9*'All Sales'!$L$2,0) -> 2217.6
A10: 44228 | B10: David Wilkinson | C10: David | D10: Wilkinson | E10: North | F10: 24131 | G10: Cash | H10: 15000 | I10: =IF(F10>=H10,F10*'All Sales'!$L$2,0) -> 2413.1
A11: 44228 | B11: Chloe Fusaro | C11: Chloe | D11: Fusaro | E11: North | F11: 34353.5 | G11: Cash | H11: 15000 | I11: =IF(F11>=H11,F11*'All Sales'!$L$2,0) -> 3435.35
A12: 44256 | B12: Charlotte Edwards | C12: Charlotte | D12: Edwards | E12: North | F12: 7416.9 | G12: On Account | H12: 15000 | I12: =IF(F12>=H12,F12*'All Sales'!$L$2,0) -> 0
A13: 44256 | B13: Jonah Seitz | C13: Jonah | D13: Seitz | E13: North | F13: 8284.5 | G13: Cash | H13: 15000 | I13: =IF(F13>=H13,F13*'All Sales'!$L$2,0) -> 0
A14: 44256 | B14: Chloe Fusaro | C14: Chloe | D14: Fusaro | E14: North | F14: 10758.7 | G14: Cash | H14: 15000 | I14: =IF(F14>=H14,F14*'All Sales'!$L$2,0) -> 0
A15: 44256 | B15: David Wilkinson | C15: David | D15: Wilkinson | E15: North | F15: 12124.2 | G15: On Account | H15: 15000 | I15: =IF(F15>=H15,F15*'All Sales'!$L$2,0) -> 0
A16: 44256 | B16: Charlotte Edwards | C16: Charlotte | D16: Edwards | E16: North | F16: 14392 | G16: Credit Card | H16: 15000 | I16: =IF(F16>=H16,F16*'All Sales'!$L$2,0) -> 0
A17: 44256 | B17: Jonah Seitz | C17: Jonah | D17: Seitz | E17: North | F17: 15246 | G17: Credit Card | H17: 15000 | I17: =IF(F17>=H17,F17*'All Sales'!$L$2,0) -> 1524.6
A18: 44256 | B18: Charlotte Edwards | C18: Charlotte | D18: Edwards | E18: North | F18: 17335.2 | G18: On Account | H18: 15000 | I18: =IF(F18>=H18,F18*'All Sales'!$L$2,0) -> 1733.52
... A97: 44531 | B97: Jonah Seitz | C97: Jonah | D97: Seitz | E97: North | F97: 43974 | G97: Credit Card | H97: 15000 | I97: =IF(F97>=H97,F97*'All Sales'!$L$2,0) -> 4397.4

Sheet South
A1: Month | B1: Employee | C1: First Name | D1: Last Name | E1: Sales Area | F1: Sales Amount | G1: Payment Type | H1: Targets | I1: Commissions
A2: 44197 | B2: Olivia Cheung | C2: Olivia | D2: Cheung | E2: South | F2: 3008.4 | G2: Cash | H2: 15000 | I2: =IF(F2>=H2,F2*'All Sales'!$L$2,0) -> 0 | K2: Salesperson Name | L2: {=TRANSPOSE(_xlfn.UNIQUE(_xlfn._xlws.SORT(C2:C100)))} -> Annabel | M2: Cory | N2: Emily | O2: Jason | P2: Olivia
A3: 44197 | B3: Jason Jackaki | C3: Jason | D3: Jackaki | E3: South | F3: 7221.6 | G3: On Account | H3: 15000 | I3: =IF(F3>=H3,F3*'All Sales'!$L$2,0) -> 0 | K3: Total Sales | L3: =SUMIFS($F$2:$F$100,$C$2:$C$100,L2) -> 482889 | M3: =SUMIFS($F$2:$F$100,$C$2:$C$100,M2) -> 323152.3 | N3: =SUMIFS($F$2:$F$100,$C$2:$C$100,N2) -> 331096.8 | O3: =SUMIFS($F$2:$F$100,$C$2:$C$100,O2) -> 285253.1 | P3: =SUMIFS($F$2:$F$100,$C$2:$C$100,P2) -> 390105.1
A4: 44197 | B4: Olivia Cheung | C4: Olivia | D4: Cheung | E4: South | F4: 10903.2 | G4: Cash | H4: 15000 | I4: =IF(F4>=H4,F4*'All Sales'!$L$2,0) -> 0
A5: 44197 | B5: Annabel Mettick | C5: Annabel | D5: Mettick | E5: South | F5: 14616 | G5: Cash | H5: 15000 | I5: =IF(F5>=H5,F5*'All Sales'!$L$2,0) -> 0 | P5: Back to Cover Page
A6: 44197 | B6: Emily Whelan | C6: Emily | D6: Whelan | E6: South | F6: 18885.9 | G6: On Account | H6: 15000 | I6: =IF(F6>=H6,F6*'All Sales'!$L$2,0) -> 1888.59
A7: 44197 | B7: Emily Whelan | C7: Emily | D7: Whelan | E7: South | F7: 24236 | G7: Credit Card | H7: 15000 | I7: =IF(F7>=H7,F7*'All Sales'!$L$2,0) -> 2423.6
A8: 44228 | B8: Annabel Mettick | C8: Annabel | D8: Mettick | E8: South | F8: 3596 | G8: Cash | H8: 15000 | I8: =IF(F8>=H8,F8*'All Sales'!$L$2,0) -> 0
A9: 44228 | B9: Cory Goodwin | C9: Cory | D9: Goodwin | E9: South | F9: 6300 | G9: On Account | H9: 15000 | I9: =IF(F9>=H9,F9*'All Sales'!$L$2,0) -> 0
A10: 44228 | B10: Annabel Mettick | C10: Annabel | D10: Mettick | E10: South | F10: 6804 | G10: Credit Card | H10: 15000 | I10: =IF(F10>=H10,F10*'All Sales'!$L$2,0) -> 0
A11: 44228 | B11: Jason Jackaki | C11: Jason | D11: Jackaki | E11: South | F11: 8524.4 | G11: On Account | H11: 15000 | I11: =IF(F11>=H11,F11*'All Sales'!$L$2,0) -> 0
A12: 44228 | B12: Annabel Mettick | C12: Annabel | D12: Mettick | E12: South | F12: 8772 | G12: On Account | H12: 15000 | I12: =IF(F12>=H12,F12*'All Sales'!$L$2,0) -> 0
A13: 44228 | B13: Annabel Mettick | C13: Annabel | D13: Mettick | E13: South | F13: 17328.3 | G13: On Account | H13: 15000 | I13: =IF(F13>=H13,F13*'All Sales'!$L$2,0) -> 1732.83
A14: 44228 | B14: Cory Goodwin | C14: Cory | D14: Goodwin | E14: South | F14: 21438.9 | G14: Credit Card | H14: 15000 | I14: =IF(F14>=H14,F14*'All Sales'!$L$2,0) -> 2143.89
A15: 44228 | B15: Jason Jackaki | C15: Jason | D15: Jackaki | E15: South | F15: 26556.8 | G15: Cash | H15: 15000 | I15: =IF(F15>=H15,F15*'All Sales'!$L$2,0) -> 2655.68
A16: 44228 | B16: Jason Jackaki | C16: Jason | D16: Jackaki | E16: South | F16: 33132.6 | G16: On Account | H16: 15000 | I16: =IF(F16>=H16,F16*'All Sales'!$L$2,0) -> 3313.26
A17: 44256 | B17: Annabel Mettick | C17: Annabel | D17: Mettick | E17: South | F17: 6544.8 | G17: Credit Card | H17: 15000 | I17: =IF(F17>=H17,F17*'All Sales'!$L$2,0) -> 0
... A100: 44531 | B100: Olivia Cheung | C100: Olivia | D100: Cheung | E100: South | F100: 43593.6 | G100: Cash | H100: 15000 | I100: =IF(F100>=H100,F100*'All Sales'!$L$2,0) -> 4359.36

Sheet East
A1: Month | B1: Employee | C1: First Name | D1: Last Name | E1: Sales Area | F1: Sales Amount | G1: Payment Type | H1: Targets | I1: Commissions
A2: 44197 | B2: Reza Jafari | C2: Reza | D2: Jafari | E2: East | F2: 2954.7 | G2: Cash | H2: 15000 | I2: =IF(F2>=H2,F2*'All Sales'!$L$2,0) -> 0
A3: 44197 | B3: Bryan Maldonado | C3: Bryan | D3: Maldonado | E3: East | F3: 6796.8 | G3: Credit Card | H3: 15000 | I3: =IF(F3>=H3,F3*'All Sales'!$L$2,0) -> 0 | K3: Salesperson Name | L3: {=TRANSPOSE(_xlfn.UNIQUE(_xlfn._xlws.SORT(C2:C97)))} -> Ashley | M3: Bryan | N3: Derek | O3: Gordon | P3: Reza
A4: 44197 | B4: Bryan Maldonado | C4: Bryan | D4: Maldonado | E4: East | F4: 8188 | G4: On Account | H4: 15000 | I4: =IF(F4>=H4,F4*'All Sales'!$L$2,0) -> 0 | K4: Total Sales | L4: {=SUMIFS($F$2:$F$97,$C$2:$C$97,_xlfn.ANCHORARRAY(L3))} -> 368364.8 | M4: 227895.8 | N4: 371911.9 | O4: 310854.5 | P4: 526806.6
A5: 44197 | B5: Reza Jafari | C5: Reza | D5: Jafari | E5: East | F5: 9058.4 | G5: Credit Card | H5: 15000 | I5: =IF(F5>=H5,F5*'All Sales'!$L$2,0) -> 0
A6: 44197 | B6: Bryan Maldonado | C6: Bryan | D6: Maldonado | E6: East | F6: 12096 | G6: On Account | H6: 15000 | I6: =IF(F6>=H6,F6*'All Sales'!$L$2,0) -> 0 | P6: Back to Cover Page
A7: 44197 | B7: Ashley Almanza | C7: Ashley | D7: Almanza | E7: East | F7: 15029 | G7: Cash | H7: 15000 | I7: =IF(F7>=H7,F7*'All Sales'!$L$2,0) -> 1502.9
A8: 44197 | B8: Ashley Almanza | C8: Ashley | D8: Almanza | E8: East | F8: 15264 | G8: Cash | H8: 15000 | I8: =IF(F8>=H8,F8*'All Sales'!$L$2,0) -> 1526.4
A9: 44197 | B9: Ashley Almanza | C9: Ashley | D9: Almanza | E9: East | F9: 17353.6 | G9: Credit Card | H9: 15000 | I9: =IF(F9>=H9,F9*'All Sales'!$L$2,0) -> 1735.36
A10: 44197 | B10: Derek Godwin | C10: Derek | D10: Godwin | E10: East | F10: 20140 | G10: On Account | H10: 15000 | I10: =IF(F10>=H10,F10*'All Sales'!$L$2,0) -> 2014
A11: 44197 | B11: Derek Godwin | C11: Derek | D11: Godwin | E11: East | F11: 35649 | G11: Credit Card | H11: 15000 | I11: =IF(F11>=H11,F11*'All Sales'!$L$2,0) -> 3564.9
A12: 44228 | B12: Gordon Beswick | C12: Gordon | D12: Beswick | E12: East | F12: 7717.5 | G12: On Account | H12: 15000 | I12: =IF(F12>=H12,F12*'All Sales'!$L$2,0) -> 0
A13: 44228 | B13: Gordon Beswick | C13: Gordon | D13: Beswick | E13: East | F13: 11617.6 | G13: Cash | H13: 15000 | I13: =IF(F13>=H13,F13*'All Sales'!$L$2,0) -> 0
A14: 44228 | B14: Derek Godwin | C14: Derek | D14: Godwin | E14: East | F14: 19431 | G14: Cash | H14: 15000 | I14: =IF(F14>=H14,F14*'All Sales'!$L$2,0) -> 1943.1
A15: 44228 | B15: Ashley Almanza | C15: Ashley | D15: Almanza | E15: East | F15: 21169.6 | G15: Cash | H15: 15000 | I15: =IF(F15>=H15,F15*'All Sales'!$L$2,0) -> 2116.96
A16: 44228 | B16: Reza Jafari | C16: Reza | D16: Jafari | E16: East | F16: 29158.4 | G16: Cash | H16: 15000 | I16: =IF(F16>=H16,F16*'All Sales'!$L$2,0) -> 2915.84
A17: 44228 | B17: Derek Godwin | C17: Derek | D17: Godwin | E17: East | F17: 30305 | G17: Credit Card | H17: 15000 | I17: =IF(F17>=H17,F17*'All Sales'!$L$2,0) -> 3030.5
A18: 44228 | B18: Gordon Beswick | C18: Gordon | D18: Beswick | E18: East | F18: 43184.4 | G18: On Account | H18: 15000 | I18: =IF(F18>=H18,F18*'All Sales'!$L$2,0) -> 4318.44
... A97: 44531 | B97: Ashley Almanza | C97: Ashley | D97: Almanza | E97: East | F97: 45801 | G97: Cash | H97: 15000 | I97: =IF(F97>=H97,F97*'All Sales'!$L$2,0) -> 4580.1

Sheet West
A1: Month | B1: Employee | C1: First Name | D1: Last Name | E1: Sales Area | F1: Sales Amount | G1: Payment Type | H1: Targets | I1: Commissions
A2: 44197 | B2: Spencer Cruz | C2: Spencer | D2: Cruz | E2: West | F2: 3637.21 | G2: Credit Card | H2: 15000 | I2: =IF(F2>=H2,F2*'All Sales'!$L$2,0) -> 0
A3: 44197 | B3: Ally Bryant | C3: Ally | D3: Bryant | E3: West | F3: 3918.6 | G3: Cash | H3: 15000 | I3: =IF(F3>=H3,F3*'All Sales'!$L$2,0) -> 0 | K3: Salesperson Name | L3: {=TRANSPOSE(_xlfn.UNIQUE(_xlfn._xlws.SORT(C2:C197)))} -> Ally | M3: Josh | N3: Nina | O3: Spencer | P3: Tia
A4: 44197 | B4: Nina McDonald | C4: Nina | D4: McDonald | E4: West | F4: 694.54 | G4: On Account | H4: 15000 | I4: =IF(F4>=H4,F4*'All Sales'!$L$2,0) -> 0 | K4: Total Sales | L4: {=SUMIFS($F$2:$F$197,$C$2:$C$197,_xlfn.ANCHORARRAY(L3))} -> 466269.1 | M4: 447097.75 | N4: 297695.09 | O4: 427071.26 | P4: 256493.49
A5: 44197 | B5: Spencer Cruz | C5: Spencer | D5: Cruz | E5: West | F5: 3112.72 | G5: On Account | H5: 15000 | I5: =IF(F5>=H5,F5*'All Sales'!$L$2,0) -> 0
A6: 44197 | B6: Nina McDonald | C6: Nina | D6: McDonald | E6: West | F6: 1001.92 | G6: On Account | H6: 15000 | I6: =IF(F6>=H6,F6*'All Sales'!$L$2,0) -> 0 | P6: Back to Cover Page
A7: 44197 | B7: Josh Sutherland | C7: Josh | D7: Sutherland | E7: West | F7: 1638.56 | G7: Credit Card | H7: 15000 | I7: =IF(F7>=H7,F7*'All Sales'!$L$2,0) -> 0
A8: 44197 | B8: Ally Bryant | C8: Ally | D8: Bryant | E8: West | F8: 1910.8 | G8: Cash | H8: 15000 | I8: =IF(F8>=H8,F8*'All Sales'!$L$2,0) -> 0
A9: 44197 | B9: Nina McDonald | C9: Nina | D9: McDonald | E9: West | F9: 765.82 | G9: On Account | H9: 15000 | I9: =IF(F9>=H9,F9*'All Sales'!$L$2,0) -> 0
A10: 44197 | B10: Ally Bryant | C10: Ally | D10: Bryant | E10: West | F10: 765.86 | G10: Cash | H10: 15000 | I10: =IF(F10>=H10,F10*'All Sales'!$L$2,0) -> 0
A11: 44197 | B11: Spencer Cruz | C11: Spencer | D11: Cruz | E11: West | F11: 4671.6 | G11: Credit Card | H11: 15000 | I11: =IF(F11>=H11,F11*'All Sales'!$L$2,0) -> 0
A12: 44197 | B12: Nina McDonald | C12: Nina | D12: McDonald | E12: West | F12: 1945.6 | G12: Credit Card | H12: 15000 | I12: =IF(F12>=H12,F12*'All Sales'!$L$2,0) -> 0
A13: 44197 | B13: Ally Bryant | C13: Ally | D13: Bryant | E13: West | F13: 1017.6 | G13: Cash | H13: 15000 | I13: =IF(F13>=H13,F13*'All Sales'!$L$2,0) -> 0
A14: 44197 | B14: Josh Sutherland | C14: Josh | D14: Sutherland | E14: West | F14: 909.86 | G14: On Account | H14: 15000 | I14: =IF(F14>=H14,F14*'All Sales'!$L$2,0) -> 0
A15: 44197 | B15: Nina McDonald | C15: Nina | D15: McDonald | E15: West | F15: 6945.4 | G15: On Account | H15: 15000 | I15: =IF(F15>=H15,F15*'All Sales'!$L$2,0) -> 0
A16: 44197 | B16: Nina McDonald | C16: Nina | D16: McDonald | E16: West | F16: 7658.2 | G16: On Account | H16: 15000 | I16: =IF(F16>=H16,F16*'All Sales'!$L$2,0) -> 0
A17: 44197 | B17: Ally Bryant | C17: Ally | D17: Bryant | E17: West | F17: 7658.6 | G17: Cash | H17: 15000 | I17: =IF(F17>=H17,F17*'All Sales'!$L$2,0) -> 0
A18: 44197 | B18: Josh Sutherland | C18: Josh | D18: Sutherland | E18: West | F18: 9098.6 | G18: On Account | H18: 15000 | I18: =IF(F18>=H18,F18*'All Sales'!$L$2,0) -> 0
... A197: 44531 | B197: Nina McDonald | C197: Nina | D197: McDonald | E197: West | F197: 8914.5 | G197: Credit Card | H197: 15000 | I197: =IF(F197>=H197,F197*'All Sales'!$L$2,0) -> 0

Sheet Copy of All Sales
A1: Month | B1: First Name | C1: Last Name | D1: Employee | E1: Employee | F1: Sales Area | G1: Sales Amount | H1: Payment Type | I1: Targets | J1: Commissions | K1: Over/Under | M1: Commission
A2: 44197 | B2: Reza | C2: Jafari | D2: Reza Jafari | E2: {=TRIM(D2:D488)} -> Reza Jafari | F2: East | G2: 2954.7 | H2: Cash | I2: 15000 | J2: =IF(G2>=I2,G2*$M$2,0) -> 0 | K2: ='Copy of All Sales'!$G2-'Copy of All Sales'!$I2 -> -12045.3 | M2: 0.1
A3: 44197 | B3: Bryan | C3: Maldonado | D3: Bryan Maldonado | E3: Bryan Maldonado | F3: East | G3: 6796.8 | H3: Credit Card | I3: 15000 | J3: =IF(G3>=I3,G3*$M$2,0) -> 0 | K3: ='Copy of All Sales'!$G3-'Copy of All Sales'!$I3 -> -8203.2 | O3: Back to Cover Page
A4: 44197 | B4: Bryan | C4: Maldonado | D4: Bryan Maldonado | E4: Bryan Maldonado | F4: East | G4: 8188 | H4: On Account | I4: 15000 | J4: =IF(G4>=I4,G4*$M$2,0) -> 0 | K4: ='Copy of All Sales'!$G4-'Copy of All Sales'!$I4 -> -6812
A5: 44197 | B5: Reza | C5: Jafari | D5: Reza Jafari | E5: Reza Jafari | F5: East | G5: 9058.4 | H5: Credit Card | I5: 15000 | J5: =IF(G5>=I5,G5*$M$2,0) -> 0 | K5: ='Copy of All Sales'!$G5-'Copy of All Sales'!$I5 -> -5941.6
A6: 44197 | B6: Bryan | C6: Maldonado | D6: Bryan Maldonado | E6: Bryan Maldonado | F6: East | G6: 12096 | H6: On Account | I6: 15000 | J6: =IF(G6>=I6,G6*$M$2,0) -> 0 | K6: ='Copy of All Sales'!$G6-'Copy of All Sales'!$I6 -> -2904
A7: 44197 | B7: Ashley | C7: Almanza | D7: Ashley Almanza | E7: Ashley Almanza | F7: East | G7: 15029 | H7: Cash | I7: 15000 | J7: =IF(G7>=I7,G7*$M$2,0) -> 1502.9 | K7: ='Copy of All Sales'!$G7-'Copy of All Sales'!$I7 -> 29
A8: 44197 | B8: Ashley | C8: Almanza | D8: Ashley Almanza | E8: Ashley Almanza | F8: East | G8: 15264 | H8: Cash | I8: 15000 | J8: =IF(G8>=I8,G8*$M$2,0) -> 1526.4 | K8: ='Copy of All Sales'!$G8-'Copy of All Sales'!$I8 -> 264
A9: 44197 | B9: Ashley | C9: Almanza | D9: Ashley Almanza | E9: Ashley Almanza | F9: East | G9: 17353.6 | H9: Credit Card | I9: 15000 | J9: =IF(G9>=I9,G9*$M$2,0) -> 1735.36 | K9: ='Copy of All Sales'!$G9-'Copy of All Sales'!$I9 -> 2353.6
A10: 44197 | B10: Derek | C10: Godwin | D10: Derek Godwin | E10: Derek Godwin | F10: East | G10: 20140 | H10: On Account | I10: 15000 | J10: =IF(G10>=I10,G10*$M$2,0) -> 2014 | K10: ='Copy of All Sales'!$G10-'Copy of All Sales'!$I10 -> 5140
A11: 44197 | B11: Derek | C11: Godwin | D11: Derek Godwin | E11: Derek Godwin | F11: East | G11: 35649 | H11: Credit Card | I11: 15000 | J11: =IF(G11>=I11,G11*$M$2,0) -> 3564.9 | K11: ='Copy of All Sales'!$G11-'Copy of All Sales'!$I11 -> 20649
A12: 44228 | B12: Gordon | C12: Beswick | D12: Gordon Beswick | E12: Gordon Beswick | F12: East | G12: 7717.5 | H12: On Account | I12: 15000 | J12: =IF(G12>=I12,G12*$M$2,0) -> 0 | K12: ='Copy of All Sales'!$G12-'Copy of All Sales'!$I12 -> -7282.5
A13: 44228 | B13: Gordon | C13: Beswick | D13: Gordon Beswick | E13: Gordon Beswick | F13: East | G13: 11617.6 | H13: Cash | I13: 15000 | J13: =IF(G13>=I13,G13*$M$2,0) -> 0 | K13: ='Copy of All Sales'!$G13-'Copy of All Sales'!$I13 -> -3382.4
A14: 44228 | B14: Derek | C14: Godwin | D14: Derek Godwin | E14: Derek Godwin | F14: East | G14: 19431 | H14: Cash | I14: 15000 | J14: =IF(G14>=I14,G14*$M$2,0) -> 1943.1 | K14: ='Copy of All Sales'!$G14-'Copy of All Sales'!$I14 -> 4431
A15: 44228 | B15: Ashley | C15: Almanza | D15: Ashley Almanza | E15: Ashley Almanza | F15: East | G15: 21169.6 | H15: Cash | I15: 15000 | J15: =IF(G15>=I15,G15*$M$2,0) -> 2116.96 | K15: ='Copy of All Sales'!$G15-'Copy of All Sales'!$I15 -> 6169.6
... A292: 44531 | B292: Olivia | C292: Cheung | D292: Olivia Cheung | E292: Olivia Cheung | F292: South | G292: 43593.6 | H292: Cash | I292: 15000 | J292: =IF(G292>=I292,G292*$M$2,0) -> 4359.36 | K292: ='Copy of All Sales'!$G292-'Copy of All Sales'!$I292 -> 28593.6
A293: 44197 | F293: West | G293: 3637.21 | H293: Credit Card | I293: 15000 | J293: =IF(G293>=I293,G293*$M$2,0) -> 0 | K293: ='Copy of All Sales'!$G293-'Copy of All Sales'!$I293 -> -11362.79
A294: 44197 | F294: West | G294: 3918.6 | H294: Cash | I294: 15000 | J294: =IF(G294>=I294,G294*$M$2,0) -> 0 | K294: ='Copy of All Sales'!$G294-'Copy of All Sales'!$I294 -> -11081.4
A295: 44197 | F295: West | G295: 694.54 | H295: On Account | I295: 15000 | J295: =IF(G295>=I295,G295*$M$2,0) -> 0 | K295: ='Copy of All Sales'!$G295-'Copy of All Sales'!$I295 -> -14305.46
A296: 44197 | F296: West | G296: 3112.72 | H296: On Account | I296: 15000 | J296: =IF(G296>=I296,G296*$M$2,0) -> 0 | K296: ='Copy of All Sales'!$G296-'Copy of All Sales'!$I296 -> -11887.28
A297: 44197 | F297: West | G297: 1001.92 | H297: On Account | I297: 15000 | J297: =IF(G297>=I297,G297*$M$2,0) -> 0 | K297: ='Copy of All Sales'!$G297-'Copy of All Sales'!$I297 -> -13998.08
A298: 44197 | F298: West | G298: 1638.56 | H298: Credit Card | I298: 15000 | J298: =IF(G298>=I298,G298*$M$2,0) -> 0 | K298: ='Copy of All Sales'!$G298-'Copy of All Sales'!$I298 -> -13361.44
A299: 44197 | F299: West | G299: 1910.8 | H299: Cash | I299: 15000 | J299: =IF(G299>=I299,G299*$M$2,0) -> 0 | K299: ='Copy of All Sales'!$G299-'Copy of All Sales'!$I299 -> -13089.2
A300: 44197 | F300: West | G300: 765.82 | H300: On Account | I300: 15000 | J300: =IF(G300>=I300,G300*$M$2,0) -> 0 | K300: ='Copy of All Sales'!$G300-'Copy of All Sales'!$I300 -> -14234.18
A301: 44197 | F301: West | G301: 765.86 | H301: Cash | I301: 15000 | J301: =IF(G301>=I301,G301*$M$2,0) -> 0 | K301: ='Copy of All Sales'!$G301-'Copy of All Sales'!$I301 -> -14234.14
A302: 44197 | F302: West | G302: 4671.6 | H302: Credit Card | I302: 15000 | J302: =IF(G302>=I302,G302*$M$2,0) -> 0 | K302: ='Copy of All Sales'!$G302-'Copy of All Sales'!$I302 -> -10328.4
A303: 44197 | F303: West | G303: 1945.6 | H303: Credit Card | I303: 15000 | J303: =IF(G303>=I303,G303*$M$2,0) -> 0 | K303: ='Copy of All Sales'!$G303-'Copy of All Sales'!$I303 -> -13054.4
A304: 44197 | F304: West | G304: 1017.6 | H304: Cash | I304: 15000 | J304: =IF(G304>=I304,G304*$M$2,0) -> 0 | K304: ='Copy of All Sales'!$G304-'Copy of All Sales'!$I304 -> -13982.4
A305: 44197 | F305: West | G305: 909.86 | H305: On Account | I305: 15000 | J305: =IF(G305>=I305,G305*$M$2,0) -> 0 | K305: ='Copy of All Sales'!$G305-'Copy of All Sales'!$I305 -> -14090.14
A306: 44197 | B306: Nina | C306: McDonald | D306: Nina McDonald | E306: Nina McDonald | F306: West | G306: 6945.4 | H306: On Account | I306: 15000 | J306: =IF(G306>=I306,G306*$M$2,0) -> 0 | K306: ='Copy of All Sales'!$G306-'Copy of All Sales'!$I306 -> -8054.6
A307: 44197 | B307: Nina | C307: McDonald | D307: Nina McDonald | E307: Nina McDonald | F307: West | G307: 7658.2 | H307: On Account | I307: 15000 | J307: =IF(G307>=I307,G307*$M$2,0) -> 0 | K307: ='Copy of All Sales'!$G307-'Copy of All Sales'!$I307 -> -7341.8
A308: 44197 | B308: Ally | C308: Bryant | D308: Ally Bryant | E308: Ally Bryant | F308: West | G308: 7658.6 | H308: Cash | I308: 15000 | J308: =IF(G308>=I308,G308*$M$2,0) -> 0 | K308: ='Copy of All Sales'!$G308-'Copy of All Sales'!$I308 -> -7341.4
A309: 44197 | B309: Josh | C309: Sutherland | D309: Josh Sutherland | E309: Josh Sutherland | F309: West | G309: 9098.6 | H309: On Account | I309: 15000 | J309: =IF(G309>=I309,G309*$M$2,0) -> 0 | K309: ='Copy of All Sales'!$G309-'Copy of All Sales'!$I309 -> -5901.4
A310: 44197 | B310: Nina | C310: McDonald | D310: Nina McDonald | E310: Nina McDonald | F310: West | G310: 10019.2 | H310: On Account | I310: 15000 | J310: =IF(G310>=I310,G310*$M$2,0) -> 0 | K310: ='Copy of All Sales'!$G310-'Copy of All Sales'!$I310 -> -4980.8
A311: 44197 | B311: Ally | C311: Bryant | D311: Ally Bryant | E311: Ally Bryant | F311: West | G311: 10176 | H311: Cash | I311: 15000 | J311: =IF(G311>=I311,G311*$M$2,0) -> 0 | K311: ='Copy of All Sales'!$G311-'Copy of All Sales'!$I311 -> -4824
A312: 44197 | B312: Josh | C312: Sutherland | D312: Josh Sutherland | E312: Josh Sutherland | F312: West | G312: 16385.6 | H312: Credit Card | I312: 15000 | J312: =IF(G312>=I312,G312*$M$2,0) -> 1638.56 | K312: ='Copy of All Sales'!$G312-'Copy of All Sales'!$I312 -> 1385.6
A313: 44197 | B313: Ally | C313: Bryant | D313: Ally Bryant | E313: Ally Bryant | F313: West | G313: 19108 | H313: Cash | I313: 15000 | J313: =IF(G313>=I313,G313*$M$2,0) -> 1910.8 | K313: ='Copy of All Sales'!$G313-'Copy of All Sales'!$I313 -> 4108
A314: 44197 | B314: Nina | C314: McDonald | D314: Nina McDonald | E314: Nina McDonald | F314: West | G314: 19456 | H314: Credit Card | I314: 15000 | J314: =IF(G314>=I314,G314*$M$2,0) -> 1945.6 | K314: ='Copy of All Sales'!$G314-'Copy of All Sales'!$I314 -> 4456
A315: 44197 | B315: Spencer | C315: Cruz | D315: Spencer Cruz | E315: Spencer Cruz | F315: West | G315: 31127.2 | H315: On Account | I315: 15000 | J315: =IF(G315>=I315,G315*$M$2,0) -> 3112.72 | K315: ='Copy of All Sales'!$G315-'Copy of All Sales'!$I315 -> 16127.2
A316: 44197 | B316: Spencer | C316: Cruz | D316: Spencer Cruz | E316: Spencer Cruz | F316: West | G316: 36372.1 | H316: Credit Card | I316: 15000 | J316: =IF(G316>=I316,G316*$M$2,0) -> 3637.21 | K316: ='Copy of All Sales'!$G316-'Copy of All Sales'!$I316 -> 21372.1
...

Sheet Chart
C1: Chart Title: | D1: Sales 2021
P2: Sales Area | Q2: Sales | R2: Commission
P3: North | Q3: 1945833.2 | R3: 157168.13
P4: West | Q4: 1894626.7 | R4: 128660.96
P5: South | Q5: 1812496.3 | R5: 138552.42
P6: East | Q6: 1805833.6 | R6: 147698.53
P7: Grand Total | Q7: 7458789.8 | R7: 572080.04 | T7: Back to Cover Page

Sheet Sales Analysis
N3: Back to Cover Page

Sheet New Staff
A1: First Name | B1: Last Name | C1: Area
A2: Brittany | B2: Gault | C2: NE
A3: Nicole | B3: Maier | C3: NE | N3: Back to Cover Page
A4: Clay | B4: Corbin | C4: NE
A5: Ashley | B5: Delange | C5: NE
A6: Jennifer | B6: Vazquez | C6: NE
A7: Manny | B7: Webster | C7: NW
A8: Luke | B8: Redenbaugh | C8: NW
A9: Debbie | B9: Godoy | C9: NW
A10: Elizabeth | B10: Lambert | C10: NW
A11: Joel | B11: Jones | C11: NW
A12: Ebony | B12: Pane | C12: SE
A13: Riley | B13: Sweeny | C13: SE
A14: Alex | B14: Ward | C14: SE
A15: Pat | B15: Hanks | C15: SE
... A21: Sam | B21: Jessup | C21: SW
